<?xml version="1.0"?>
<!-- Revolute-Revolute Manipulator -->
<robot name="diff_drive" xmlns:xacro="http://www.ros.org/wiki/xacro">

<xacro:property name="a" value="${load_yaml('/tsim/config/diff_params.yaml')}" />


  <!-- Base Link -->
  <link name="base_link">
    <visual>
      <origin xyz="0 0 0" rpy="0 0 0" />
      <geometry>
          <box size="${a['chassis_length']} ${a['wheel_base']} ${a['chassis_thickness']} "/>
      </geometry>
      <material name="blue">
        <color rgba="0 0.5 1 1"/>
      </material>
    </visual>
  </link>

  <!-- caster -->
  <link name="caster">
    <visual>
      <origin xyz="0.2 0 -0.125" rpy="0 0 0" />
      <geometry>
          <sphere radius="${a['wheel_radius']}"/>
      </geometry>
      <material name="blue">
        <color rgba="0 0.5 1 1"/>
      </material>
    </visual>
  </link>
  <joint name="caster_chassis" type="floating">
    <parent link="base_link"/>
    <child link="caster"/>
    <origin xyz="0 -0.30 0" rpy="0 0 0" /> 
  </joint>


  <!-- Right Wheel -->
  <link name="right_wheel">
    <visual>
      <origin xyz="0 0 0" rpy="1.570795 0 0" />
      <geometry>
          <cylinder length="${a['wheel_width']}" radius="${a['wheel_radius']}" />
      </geometry>
      <material name="black">
        <color rgba="0.05 0.05 0.05 1"/>
      </material>
    </visual>
  </link>
  <joint name="joint_right_wheel" type="continuous">
    <parent link="base_link"/>
    <child link="right_wheel"/>
    <origin xyz="0 -0.30 0" rpy="0 0 0" /> 
    <axis xyz="0 1 0" />
  </joint>

  <!-- Left Wheel -->
  <link name="left_wheel">
    <visual>
      <origin xyz="0 0 0" rpy="1.570795 0 0" />
      <geometry>
          <cylinder length="${a['wheel_width']}" radius="${a['wheel_radius']}" />
      </geometry>
      <material name="black"/>
    </visual>
  </link>
  <joint name="joint_left_wheel" type="continuous">
    <parent link="base_link"/>
    <child link="left_wheel"/>
    <origin xyz="0 0.30 0" rpy="0 0 0" /> 
    <axis xyz="0 1 0" />
  </joint>




</robot>