<?xml version="1.0"?>
<robot name="diff_drive" xmlns:xacro="http://www.ros.org/wiki/xacro">

<xacro:property name="yaml_file" value="$(find nuturtle_description)/config/diff_params.yaml" />
<xacro:property name="a" value="${load_yaml(yaml_file)}"/>

<xacro:property name="l" value="${a['chassis_length']}" />
<xacro:property name="w" value="${a['wheel_base']}" />
<xacro:property name="h" value="${a['chassis_thickness']}" />
<xacro:property name="w_off" value="${a['wheel_axle_offset']}" />
<xacro:property name="r" value="${a['wheel_radius']}" />
<xacro:property name="wid" value="${a['wheel_width']}" />
<xacro:property name="mass_c" value="${a['chassis_mass']}" />
<xacro:property name="mass_w" value="${a['wheel_mass']}" />
<xacro:property name="caster_rad" value="${(r-w_off)/2}" />


  <link name="base_link"/>

  <joint name="base_joint" type="fixed">
    <parent link="base_link"/>
    <child link="body_link"/>
     <origin xyz="${l/2 - r} 0.0 ${h/2 +r- w_off}" rpy="0 0 0"/>
  </joint>


  <link name="body_link">
    <visual>
     <origin xyz="0 0 0" rpy="0 0 0" />
      <geometry>
          <box size="${l} ${w-wid} ${h} "/>
      </geometry>
      <material name="color1">
        <color rgba="0.1 0.3 1 0.6"/>
      </material>
    </visual>
    <collision>
      <origin xyz="${l/2 - r} 0 ${h/2 + r- w_off}" rpy="0 0 0" />
      <geometry>
         <box size="${l} ${w-wid} ${h} "/>
      </geometry>
    </collision>
   
     <inertial>
      <mass value="${mass_c}"/>
     <inertia  ixx="${mass_c * ((h*h)+ (w-wid)*(w-wid))/12}" ixy="0" ixz="0"
              iyy="${mass_c * ((w-wid)*(w-wid) + l*l)/12}" iyz="0"
              izz="${mass_c * (h*h + l*l)/12 }"/> />
     </inertial>
</link>


<link name ="base_scan">

</link> 

   <joint name="scan_joint" type="fixed">
    <parent link="base_link"/>
    <child link="base_scan"/>
    <origin xyz="0 0 ${h/2 + 0.03/2}" rpy="0 0 0" /> 
    <axis xyz="0 1 0" />
  </joint>
   

   <!-- Right Wheel -->
  <link name="right_wheel">
    <visual>
       <origin xyz="0 ${-1*wid/2} 0" rpy="1.570795 0 0" />
      <geometry>  
          <cylinder length="${wid}" radius="${r}" />
      </geometry>
      <material name="color2">
        <color rgba="0 0 0 1"/>
      </material>
    </visual>
    <collision>
      <origin xyz="0 ${-1*wid/2} 0" rpy="1.570795 0 0" />
      <geometry>  
      <cylinder length="${wid}" radius="${r}" />
      </geometry>
    </collision>
    <inertial>
      <mass value="${mass_w}"/>
      <inertia  ixx="${mass_w * ((3*r*r)+ (wid*wid)) / 12.0}"
              iyy="${mass_w * ((3*r*r)+ (wid*wid)) / 12.0}" iyz="0"
              izz="${0.5 * mass_w * (r*r)}" ixy="0" ixz="0"/>

    </inertial>
  </link>

  <joint name="right_wheel_axle" type="continuous">
    <parent link="body_link"/>
    <child link="right_wheel"/>
   <origin xyz="${-l/2 + r} ${-1*(w/2-wid/2)} ${-h/2 + w_off}" rpy="0 0 0" /> 
    <axis xyz="0 1 0" />
  </joint>

  <!-- left Wheel -->
  <link name="left_wheel">
    <visual>
   <origin xyz="0 ${1*wid/2} 0" rpy="1.570795 0 0" />
      <geometry>
          <cylinder length="${wid}" radius="${r}" />
      </geometry>
      <material name="color3">
        <color rgba="0.3 0.44 0.1 0.6"/>
      </material>
    </visual>
    <collision>
      <origin xyz="0 ${1*wid/2} 0" rpy="1.570795 0 0" />
      <geometry>
      <cylinder length="${wid}" radius="${r}" />
      </geometry>
    </collision>
    <inertial>
      <mass value="${mass_w}"/>
     <inertia  ixx="${mass_w * ((3*r*r)+ (wid*wid)) / 12.0}"
              iyy="${mass_w * ((3*r*r)+ (wid*wid)) / 12.0}" iyz="0"
              izz="${0.5 * mass_w * (r*r)}" ixy="0" ixz="0"/>
    </inertial>

  </link>
  <joint name="left_wheel_axle" type="continuous">
    <parent link="body_link"/>
    <child link="left_wheel"/>
   <origin xyz="${-l/2 + r} ${1*(w/2-wid/2)} ${-h/2 + w_off}" rpy="0 0 0" /> 
    <axis xyz="0 1 0" />
  </joint>

<!-- caster Wheel -->
<link name="caster">
    <visual>
      <origin xyz="0 0 0" rpy="0 0 0" />
      <geometry>
          <sphere radius="${caster_rad }"/>
      </geometry>
      <material name="color4">
        <color rgba="0.8 0.12 1 1"/>
      </material>
    </visual>
    <collision>
      <origin xyz="0 0 0" rpy="0 0 0" />
      <geometry>
      <sphere radius="${caster_rad}"/>
      </geometry>
    </collision>
 </link> 
  <joint name="caster_chassis" type="fixed">
    <parent link="body_link"/>
    <child link="caster"/>
  <origin xyz="${l/2 - caster_rad} 0 ${-h/2 - caster_rad}" /> 
    <axis xyz = '1 1 1'/>
  </joint>


</robot>